Workbook

Sheet README
A1: EXCEL FORMULAS MASTERCLASS — Practice Workbook
A2: APEX AGI SOLUTIONS · Dummy transaction dataset + every formula in the syllabus, live and editable.
A4: Sheet | B4: What's in it | C4: How to use it
A5: Data | B5: 120 dummy transaction rows (the 14 columns you supplied). gst_amount is a live ROUND() formula. | C5: This is the source table every formula points at. Change any value and all sheets recalculate.
A6: Master | B6: Lookup tables: product master, region master, quarterly targets. | C6: Feeds VLOOKUP / HLOOKUP / INDEX-MATCH / CHOOSE and the drop-down lists.
A7: 01_Lookup | B7: VLOOKUP, HLOOKUP, INDEX+MATCH, XLOOKUP, CHOOSE | C7: Change the yellow input cells at the top and watch every result update.
A8: 02_Math | B8: SUM family, COUNT family, AVERAGE family, MAX/MIN, ROUND family, SUBTOTAL | C8: Yellow cells drive the criteria.
A9: 03_Logical | B9: IF, IFS, AND / OR / NOT, IFERROR, IFNA | C9: Nested-logic patterns you will actually use in reporting.
A10: 04_Text | B10: CONCATENATE, TEXTJOIN, LEFT/RIGHT/MID, TRIM, UPPER/LOWER/PROPER, FIND/SEARCH, SUBSTITUTE/REPLACE | C10: Includes a deliberately messy name/email column to clean.
A11: 05_DateTime | B11: TODAY, NOW, DATE, DATEDIF, EOMONTH, NETWORKDAYS, WEEKDAY | C11: Age of transaction, month-end, working days, day names.
A12: 06_DataTools | B12: Data Validation, Conditional Formatting, Pivot Tables, Text to Columns, Remove Duplicates | C12: Live drop-downs + step-by-step instructions to do each one yourself.
A14: LEGEND
A15: Yellow cells = inputs. Type your own value here.
A16: Purple monospace = the formula written out, as text, so you can read and copy it.
A17: Black text = the live formula's result.
A19: NOTE ON XLOOKUP: it needs Excel 2021 or Microsoft 365. The formula text is given on 01_Lookup, with the INDEX+MATCH equivalent running live beside it so the sheet opens cleanly in every version.

Sheet Data
A1: transaction_id | B1: customer_id | C1: transaction_date | D1: region | E1: customer_type | F1: product | G1: quantity | H1: sales_amount | I1: discount | J1: gst_amount | K1: payment_method | L1: order_status | M1: source | N1: support_tickets | P1: gst_amount = 18% of sales_amount, rounded to 2 dp (assumption — dummy data).
A2: TX000001 | B2: 104292 | C2: 45763 | D2: South | E2: Existing | F2: Compliance Suite | G2: 5 | H2: 18388.27 | I2: 0.05 | J2: =ROUND(H2*0.18,2) -> 3309.89 | K2: Bank Transfer | L2: Completed | M2: Offline | N2: 3
A3: TX000002 | B3: 100761 | C3: 45771 | D3: East | E3: New | F3: Data Analytics | G3: 1 | H3: 1336.37 | I3: 0.15 | J3: =ROUND(H3*0.18,2) -> 240.55 | K3: Bank Transfer | L3: Completed | M3: Offline | N3: 2
A4: TX000003 | B4: 102948 | C4: 46023 | D4: West | E4: Existing | F4: Compliance Suite | G4: 1 | H4: 22570.3 | I4: 0.1 | J4: =ROUND(H4*0.18,2) -> 4062.65 | K4: UPI | L4: Completed | M4: Referral | N4: 4
A5: TX000004 | B5: 101254 | C5: 45974 | D5: North | E5: Existing | F5: Payroll | G5: 3 | H5: 16672.98 | I5: 0.05 | J5: =ROUND(H5*0.18,2) -> 3001.14 | K5: Bank Transfer | L5: Completed | M5: Referral | N5: 3
A6: TX000005 | B6: 103585 | C6: 46176 | D6: Central | E6: Existing | F6: Data Analytics | G6: 5 | H6: 47856.72 | I6: 0 | J6: =ROUND(H6*0.18,2) -> 8614.21 | K6: Bank Transfer | L6: Pending | M6: Offline | N6: 3
A7: TX000006 | B7: 100307 | C7: 45887 | D7: South | E7: New | F7: Compliance Suite | G7: 1 | H7: 29067.71 | I7: 0.1 | J7: =ROUND(H7*0.18,2) -> 5232.19 | K7: Bank Transfer | L7: Cancelled | M7: Online | N7: 1
A8: TX000007 | B8: 101099 | C8: 46125 | D8: Northeast | E8: Existing | F8: Compliance Suite | G8: 3 | H8: 48775.67 | I8: 0.05 | J8: =ROUND(H8*0.18,2) -> 8779.62 | K8: Bank Transfer | L8: Pending | M8: Offline | N8: 2
A9: TX000008 | B9: 103392 | C9: 46101 | D9: South | E9: Existing | F9: Payroll | G9: 1 | H9: 38769.81 | I9: 0 | J9: =ROUND(H9*0.18,2) -> 6978.57 | K9: Cash | L9: Cancelled | M9: Offline | N9: 4
A10: TX000009 | B10: 104110 | C10: 46026 | D10: South | E10: Existing | F10: Data Analytics | G10: 4 | H10: -44430.83 | I10: 0.05 | J10: =ROUND(H10*0.18,2) -> -7997.55 | K10: Bank Transfer | L10: Refunded | M10: Online | N10: 4
A11: TX000010 | B11: 102694 | C11: 46126 | D11: North | E11: Existing | F11: Compliance Suite | G11: 3 | H11: 45929.48 | I11: 0.05 | J11: =ROUND(H11*0.18,2) -> 8267.31 | K11: Cash | L11: Completed | M11: Online | N11: 5
A12: TX000011 | B12: 102282 | C12: 46168 | D12: East | E12: New | F12: GST Filing | G12: 4 | H12: 51779.41 | I12: 0 | J12: =ROUND(H12*0.18,2) -> 9320.29 | K12: Bank Transfer | L12: Pending | M12: Referral | N12: 0
A13: TX000012 | B13: 104577 | C13: 45743 | D13: Central | E13: New | F13: GST Filing | G13: 1 | H13: 25476.19 | I13: 0.05 | J13: =ROUND(H13*0.18,2) -> 4585.71 | K13: Card | L13: Completed | M13: Offline | N13: 2
... A121: TX000120 | B121: 101404 | C121: 45960 | D121: North | E121: New | F121: GST Filing | G121: 4 | H121: 12258.94 | I121: 0.05 | J121: =ROUND(H121*0.18,2) -> 2206.61 | K121: Card | L121: Completed | M121: Online | N121: 3

Sheet Master
A1: product | B1: category | C1: unit_price | D1: owner
A2: Invoice Pro | B2: Billing | C2: 4500 | D2: Sana Fatima
A3: GST Filing | B3: Compliance | C3: 2800 | D3: Rahul Menon
A4: Payroll | B4: HR Tech | C4: 6200 | D4: Imran Qureshi
A5: Data Analytics | B5: Analytics | C5: 9800 | D5: Priya Nair
A6: Compliance Suite | B6: Compliance | C6: 12500 | D6: Rahul Menon
A9: region | B9: zone | C9: manager
A10: North | B10: Zone-A | C10: K. Sharma
A11: South | B11: Zone-B | C11: M. Reddy
A12: East | B12: Zone-C | C12: S. Das
A13: West | B13: Zone-B | C13: A. Joshi
A14: Central | B14: Zone-A | C14: N. Verma
A15: Northeast | B15: Zone-C | C15: T. Barua
A18: QUARTERLY TARGETS (horizontal table — used by HLOOKUP)
A19: metric | B19: Q1 | C19: Q2 | D19: Q3 | E19: Q4
A20: Target | B20: 1800000 | C20: 2100000 | D20: 2450000 | E20: 2900000
A21: Owner | B21: S. Iyer | C21: S. Iyer | D21: D. Kulkarni | E21: D. Kulkarni

Sheet 01_Lookup
A1: LOOKUP & REFERENCE
A2: VLOOKUP · HLOOKUP · INDEX+MATCH · XLOOKUP · CHOOSE
A3: INPUTS (edit the yellow cells)
A4: Transaction ID | B4: TX000045
A5: Product | B5: Data Analytics
A6: Quarter | B6: Q3
A7: Region | B7: South
A9: # | B9: Function | C9: What it does | D9: Formula (copy this) | E9: Live result | F9: Notes
A10: 1 | B10: VLOOKUP | C10: Unit price of the product in B5, from the product master. | D10: =VLOOKUP($B$5,Master!$A$2:$D$6,3,FALSE) | E10: =VLOOKUP($B$5,Master!$A$2:$D$6,3,FALSE()) -> 9800 | F10: 4th argument FALSE = exact match. Always use FALSE.
A11: 2 | B11: VLOOKUP | C11: Owner of that product (4th column of the same table). | D11: =VLOOKUP($B$5,Master!$A$2:$D$6,4,FALSE) | E11: =VLOOKUP($B$5,Master!$A$2:$D$6,4,FALSE()) -> Priya Nair | F11: Lookup value must sit in the FIRST column of the table range.
A12: 3 | B12: VLOOKUP + IFERROR | C12: Safe lookup — returns a friendly message instead of an N/A error. | D12: =IFERROR(VLOOKUP($B$4,Master!$A$2:$D$6,3,FALSE),"Not in master") | E12: =IFERROR(VLOOKUP($B$4,Master!$A$2:$D$6,3,FALSE()),"Not in master") -> Not in master | F12: B4 is a transaction ID, so this deliberately misses.
A13: 4 | B13: HLOOKUP | C13: Target for the quarter in B6 from the horizontal table. | D13: =HLOOKUP($B$6,Master!$B$19:$E$21,2,FALSE) | E13: =HLOOKUP($B$6,Master!$B$19:$E$21,2,FALSE()) -> 2450000 | F13: H = horizontal. Lookup row must be the TOP row of the range.
A14: 5 | B14: HLOOKUP | C14: Owner for that quarter (3rd row of the same table). | D14: =HLOOKUP($B$6,Master!$B$19:$E$21,3,FALSE) | E14: =HLOOKUP($B$6,Master!$B$19:$E$21,3,FALSE()) -> D. Kulkarni
A15: 6 | B15: INDEX + MATCH | C15: Sales amount for the transaction ID in B4. | D15: =INDEX(Data!$H$2:$H$121,MATCH($B$4,Data!$A$2:$A$121,0)) | E15: =INDEX(Data!$H$2:$H$121,MATCH($B$4,Data!$A$2:$A$121,0)) -> 5641.16 | F15: MATCH finds the ROW, INDEX returns the value. Works right-to-left, unlike VLOOKUP.
A16: 7 | B16: INDEX + MATCH | C16: Product for that same transaction ID. | D16: =INDEX(Data!$F$2:$F$121,MATCH($B$4,Data!$A$2:$A$121,0)) | E16: =INDEX(Data!$F$2:$F$121,MATCH($B$4,Data!$A$2:$A$121,0)) -> GST Filing
A17: 8 | B17: INDEX + MATCH (2-way) | C17: Manager for the region in B7 — row AND column matched. | D17: =INDEX(Master!$A$10:$C$15,MATCH($B$7,Master!$A$10:$A$15,0),MATCH("manager",Master!$A$9:$C$9,0)) | E17: =INDEX(Master!$A$10:$C$15,MATCH($B$7,Master!$A$10:$A$15,0),MATCH("manager",Master!$A$9:$C$9,0)) -> M. Reddy | F17: Two MATCHes = a true two-dimensional lookup.
A18: 9 | B18: XLOOKUP | C18: Modern replacement for VLOOKUP (Excel 2021 / 365 only). | D18: =XLOOKUP($B$5,Master!$A$2:$A$6,Master!$C$2:$C$6,"Not found") | E18: =VLOOKUP($B$5,Master!$A$2:$D$6,3,FALSE()) -> 9800 | F18: Column E runs the VLOOKUP equivalent so this file opens in any version. XLOOKUP needs no column index and has a built-in if-not-found argument.
A19: 10 | B19: XLOOKUP (reverse) | C19: Search from the bottom up — impossible with VLOOKUP. | D19: =XLOOKUP($B$5,Data!$F$2:$F$121,Data!$A$2:$A$121,"None",0,-1) | E19: =LOOKUP(2,1/(Data!$F$2:$F$121=$B$5),Data!$A$2:$A$121) -> TX000105 | F19: Column E shows the classic array workaround. The 6th argument -1 means 'search last to first'.
A20: 11 | B20: CHOOSE | C20: Pick the Nth item from a hard-coded list. | D20: =CHOOSE(2,"Bronze","Silver","Gold","Platinum") | E20: =CHOOSE(2,"Bronze","Silver","Gold","Platinum") -> Silver | F20: Index 1 = first item. Great for grade / tier labels.
A21: 12 | B21: CHOOSE + MATCH | C21: Turn the region in B7 into its zone label. | D21: =CHOOSE(MATCH($B$7,Master!$A$10:$A$15,0),"Zone-A","Zone-B","Zone-C","Zone-B","Zone-A","Zone-C") | E21: =CHOOSE(MATCH($B$7,Master!$A$10:$A$15,0),"Zone-A","Zone-B","Zone-C","Zone-B","Zone-A","Zone-C") -> Zone-B | F21: CHOOSE replaces a long nested IF when the options are fixed.
A22: 13 | B22: CHOOSE + WEEKDAY | C22: Day name for today's date. | D22: =CHOOSE(WEEKDAY(TODAY(),2),"Monday","Tuesday","Wednesday","Thursday","Friday","Saturday","Sunday") | E22: =CHOOSE(WEEKDAY(TODAY(),2),"Monday","Tuesday","Wednesday","Thursday","Friday","Saturday","Sunday") -> Thursday

Sheet 02_Math
A1: MATH & AGGREGATION
A2: SUM family · COUNT family · AVERAGE family · MAX/MIN · ROUND family · SUBTOTAL
A3: INPUTS (edit the yellow cells)
A4: Region | B4: South
A5: Product | B5: GST Filing
A6: Min sales | B6: 10000
A8: # | B8: Function | C8: What it does | D8: Formula (copy this) | E8: Live result | F8: Notes
A9: 1 | B9: SUM | C9: Total of every sales_amount. | D9: =SUM(Data!$H$2:$H$121) | E9: =SUM(Data!$H$2:$H$121) -> 2886948.2
A10: 2 | B10: SUMIF | C10: Sales for the region in B4 (one condition). | D10: =SUMIF(Data!$D$2:$D$121,$B$4,Data!$H$2:$H$121) | E10: =SUMIF(Data!$D$2:$D$121,$B$4,Data!$H$2:$H$121) -> 564865.61 | F10: Order: range, criteria, sum_range.
A11: 3 | B11: SUMIFS | C11: Sales for that region AND that product (two conditions). | D11: =SUMIFS(Data!$H$2:$H$121,Data!$D$2:$D$121,$B$4,Data!$F$2:$F$121,$B$5) | E11: =SUMIFS(Data!$H$2:$H$121,Data!$D$2:$D$121,$B$4,Data!$F$2:$F$121,$B$5) -> 148968.56 | F11: Order flips: sum_range comes FIRST in SUMIFS.
A12: 4 | B12: SUMIFS (3 criteria) | C12: Completed orders, that region, above the B6 threshold. | D12: =SUMIFS(Data!$H$2:$H$121,Data!$L$2:$L$121,"Completed",Data!$D$2:$D$121,$B$4,Data!$H$2:$H$121,">"&$B$6) | E12: =SUMIFS(Data!$H$2:$H$121,Data!$L$2:$L$121,"Completed",Data!$D$2:$D$121,$B$4,Data!$H$2:$H$121,">"&$B$6) -> 423815.76 | F12: Note the ">"&B6 syntax for a cell-driven comparison.
A13: 5 | B13: COUNT | C13: How many numeric sales values there are. | D13: =COUNT(Data!$H$2:$H$121) | E13: =COUNT(Data!$H$2:$H$121) -> 120 | F13: COUNT counts NUMBERS only.
A14: 6 | B14: COUNTA | C14: How many non-empty cells in the product column. | D14: =COUNTA(Data!$F$2:$F$121) | E14: =COUNTA(Data!$F$2:$F$121) -> 120 | F14: COUNTA counts anything that isn't blank.
A15: 7 | B15: COUNTIF | C15: Number of Refunded orders. | D15: =COUNTIF(Data!$L$2:$L$121,"Refunded") | E15: =COUNTIF(Data!$L$2:$L$121,"Refunded") -> 7
A16: 8 | B16: COUNTIFS | C16: New customers in the region in B4. | D16: =COUNTIFS(Data!$E$2:$E$121,"New",Data!$D$2:$D$121,$B$4) | E16: =COUNTIFS(Data!$E$2:$E$121,"New",Data!$D$2:$D$121,$B$4) -> 3
A17: 9 | B17: COUNTIFS (range) | C17: Transactions with sales between 10,000 and 30,000. | D17: =COUNTIFS(Data!$H$2:$H$121,">=10000",Data!$H$2:$H$121,"<=30000") | E17: =COUNTIFS(Data!$H$2:$H$121,">=10000",Data!$H$2:$H$121,"<=30000") -> 52 | F17: Same range used twice = a band.
A18: 10 | B18: AVERAGE | C18: Average ticket size across all rows. | D18: =AVERAGE(Data!$H$2:$H$121) | E18: =AVERAGE(Data!$H$2:$H$121) -> 24057.902
A19: 11 | B19: AVERAGEIF | C19: Average sales for the product in B5. | D19: =AVERAGEIF(Data!$F$2:$F$121,$B$5,Data!$H$2:$H$121) | E19: =AVERAGEIF(Data!$F$2:$F$121,$B$5,Data!$H$2:$H$121) -> 27764.757
A20: 12 | B20: AVERAGEIFS | C20: Average sales — that product, UPI payments only. | D20: =AVERAGEIFS(Data!$H$2:$H$121,Data!$F$2:$F$121,$B$5,Data!$K$2:$K$121,"UPI") | E20: =AVERAGEIFS(Data!$H$2:$H$121,Data!$F$2:$F$121,$B$5,Data!$K$2:$K$121,"UPI") -> 29722.23
A21: 13 | B21: MAX | C21: Largest single sale. | D21: =MAX(Data!$H$2:$H$121) | E21: =MAX(Data!$H$2:$H$121) -> 53976.12
A22: 14 | B22: MIN | C22: Smallest value (negative = a refund). | D22: =MIN(Data!$H$2:$H$121) | E22: =MIN(Data!$H$2:$H$121) -> -53395.17
A23: 15 | B23: MAXIFS | C23: Largest sale within the region in B4. | D23: =MAXIFS(Data!$H$2:$H$121,Data!$D$2:$D$121,$B$4) | E23: =_xlfn.MAXIFS(Data!$H$2:$H$121,Data!$D$2:$D$121,$B$4) -> 53976.12 | F23: Excel 2019+. MINIFS works identically.
A24: 16 | B24: ROUND | C24: Average ticket rounded to the nearest rupee. | D24: =ROUND(AVERAGE(Data!$H$2:$H$121),0) | E24: =ROUND(AVERAGE(Data!$H$2:$H$121),0) -> 24058 | F24: 2nd argument = decimal places. Use -3 to round to thousands.
A25: 17 | B25: ROUNDUP | C25: Always rounds away from zero. | D25: =ROUNDUP(2451.11,0) | E25: =ROUNDUP(2451.11,0) -> 2452
A26: 18 | B26: ROUNDDOWN | C26: Always rounds toward zero. | D26: =ROUNDDOWN(2451.99,0) | E26: =ROUNDDOWN(2451.99,0) -> 2451
A27: 19 | B27: SUBTOTAL (sum) | C27: Sum that IGNORES rows hidden by a filter. | D27: =SUBTOTAL(109,Data!$H$2:$H$121) | E27: =SUBTOTAL(109,Data!$H$2:$H$121) -> 2886948.2 | F27: 109 = SUM ignoring hidden rows. 9 = SUM ignoring filtered rows only.
A28: 20 | B28: SUBTOTAL (count) | C28: Visible-row count — the number in the status bar. | D28: =SUBTOTAL(103,Data!$A$2:$A$121) | E28: =SUBTOTAL(103,Data!$A$2:$A$121) -> 120 | F28: 103 = COUNTA. 101 = AVERAGE, 104 = MAX, 105 = MIN.
A29: 21 | B29: SUMPRODUCT | C29: Net revenue after discount, in one formula. | D29: =SUMPRODUCT(Data!$H$2:$H$121,1-Data!$I$2:$I$121) | E29: =SUMPRODUCT(Data!$H$2:$H$121,1-Data!$I$2:$I$121) -> 2734507.6 | F29: Multiplies two columns row-by-row, then sums. No helper column needed.

Sheet 03_Logical
A1: LOGICAL
A2: IF · IFS · AND / OR / NOT · IFERROR / IFNA
A3: INPUTS (edit the yellow cells)
A4: Row to test (2-121) | B4: 12
A5: High-value cut-off | B5: 25000
A7: # | B7: Function | C7: What it does | D7: Formula (copy this) | E7: Live result | F7: Notes
A8: 1 | B8: IF | C8: Flag the tested row as High or Standard value. | D8: =IF(INDEX(Data!$H$2:$H$121,$B$4-1)>$B$5,"High value","Standard") | E8: =IF(INDEX(Data!$H$2:$H$121,$B$4-1)>$B$5,"High value","Standard") -> High value | F8: IF(test, value_if_true, value_if_false).
A9: 2 | B9: IF (nested) | C9: Three-way bucket using IF inside IF. | D9: =IF(INDEX(Data!$H$2:$H$121,$B$4-1)<0,"Refund",IF(INDEX(Data!$H$2:$H$121,$B$4-1)>$B$5,"High","Normal")) | E9: =IF(INDEX(Data!$H$2:$H$121,$B$4-1)<0,"Refund",IF(INDEX(Data!$H$2:$H$121,$B$4-1)>$B$5,"High","Normal")) -> High | F9: Readable up to about 3 levels. Beyond that, use IFS.
A10: 3 | B10: IFS | C10: Same result, flat and readable. | D10: =IFS(INDEX(Data!$H$2:$H$121,$B$4-1)<0,"Refund",INDEX(Data!$H$2:$H$121,$B$4-1)>$B$5,"High",TRUE,"Normal") | E10: =_xlfn.IFS(INDEX(Data!$H$2:$H$121,$B$4-1)<0,"Refund",INDEX(Data!$H$2:$H$121,$B$4-1)>$B$5,"High",TRUE(),"Normal") -> High | F10: Excel 2019+. End with TRUE,<default> to catch everything else.
A11: 4 | B11: AND | C11: TRUE only when every condition holds. | D11: =AND(INDEX(Data!$L$2:$L$121,$B$4-1)="Completed",INDEX(Data!$H$2:$H$121,$B$4-1)>$B$5) | E11: =AND(INDEX(Data!$L$2:$L$121,$B$4-1)="Completed",INDEX(Data!$H$2:$H$121,$B$4-1)>$B$5) -> FALSE | F11: Returns TRUE / FALSE — usually wrapped inside an IF.
A12: 5 | B12: OR | C12: TRUE when at least one condition holds. | D12: =OR(INDEX(Data!$E$2:$E$121,$B$4-1)="New",INDEX(Data!$M$2:$M$121,$B$4-1)="Referral") | E12: =OR(INDEX(Data!$E$2:$E$121,$B$4-1)="New",INDEX(Data!$M$2:$M$121,$B$4-1)="Referral") -> TRUE
A13: 6 | B13: NOT | C13: Reverses TRUE and FALSE. | D13: =NOT(INDEX(Data!$L$2:$L$121,$B$4-1)="Completed") | E13: =NOT(INDEX(Data!$L$2:$L$121,$B$4-1)="Completed") -> TRUE
A14: 7 | B14: IF + AND | C14: The real-world pattern: escalate a support case. | D14: =IF(AND(INDEX(Data!$N$2:$N$121,$B$4-1)>=3,INDEX(Data!$H$2:$H$121,$B$4-1)>$B$5),"Escalate to CS head","Routine") | E14: =IF(AND(INDEX(Data!$N$2:$N$121,$B$4-1)>=3,INDEX(Data!$H$2:$H$121,$B$4-1)>$B$5),"Escalate to CS head","Routine") -> Routine
A15: 8 | B15: IF + OR | C15: Mark rows that need a finance review. | D15: =IF(OR(INDEX(Data!$L$2:$L$121,$B$4-1)="Refunded",INDEX(Data!$L$2:$L$121,$B$4-1)="Cancelled"),"Finance review","OK") | E15: =IF(OR(INDEX(Data!$L$2:$L$121,$B$4-1)="Refunded",INDEX(Data!$L$2:$L$121,$B$4-1)="Cancelled"),"Finance review","OK") -> OK
A16: 9 | B16: IFERROR | C16: Catches ANY error — divide-by-zero, N/A, VALUE, all of them. | D16: =IFERROR(100/0,"Cannot divide by zero") | E16: =IFERROR(100/0,"Cannot divide by zero") -> Cannot divide by zero | F16: The everyday safety net. Wrap it around any division or lookup.
A17: 10 | B17: IFERROR + division | C17: Discount as a % of sales, guarded. | D17: =IFERROR(INDEX(Data!$I$2:$I$121,$B$4-1)*INDEX(Data!$H$2:$H$121,$B$4-1)/INDEX(Data!$H$2:$H$121,$B$4-1),0) | E17: =IFERROR(INDEX(Data!$I$2:$I$121,$B$4-1)*INDEX(Data!$H$2:$H$121,$B$4-1)/INDEX(Data!$H$2:$H$121,$B$4-1),0) -> 0
A18: 11 | B18: IFNA | C18: Catches ONLY the N/A error — other errors still surface. | D18: =IFNA(VLOOKUP("Zebra Plan",Master!$A$2:$D$6,3,FALSE),"Product not in master") | E18: =_xlfn.IFNA(VLOOKUP("Zebra Plan",Master!$A$2:$D$6,3,FALSE()),"Product not in master") -> Product not in master | F18: Safer than IFERROR for lookups: a typo in your formula still shows up as an error instead of being silently hidden.
A19: 12 | B19: IF + COUNTIF | C19: Duplicate check on transaction_id. | D19: =IF(COUNTIF(Data!$A$2:$A$121,INDEX(Data!$A$2:$A$121,$B$4-1))>1,"Duplicate","Unique") | E19: =IF(COUNTIF(Data!$A$2:$A$121,INDEX(Data!$A$2:$A$121,$B$4-1))>1,"Duplicate","Unique") -> Unique

Sheet 04_Text
A1: TEXT
A2: CONCATENATE · TEXTJOIN · LEFT / RIGHT / MID · TRIM · UPPER / LOWER / PROPER · FIND / SEARCH · SUBSTITUTE / REPLACE
A3: INPUTS (edit the yellow cells)
A4: Messy name | B4: abdul AZEEZ
A5: Email | B5: rahul.menon@apexagi.co.in
A6: Coded ref | B6: TX000045-South-GST Filing
A8: # | B8: Function | C8: What it does | D8: Formula (copy this) | E8: Live result | F8: Notes
A9: 1 | B9: CONCATENATE | C9: Glue text together the old way. | D9: =CONCATENATE("Txn ",Data!A2," | ",Data!F2) | E9: =CONCATENATE("Txn ",Data!A2," | ",Data!F2) -> Txn TX000001 | Compliance Suite | F9: The & operator does the same: ="Txn "&Data!A2.
A10: 2 | B10: TEXTJOIN | C10: Join with a delimiter, skipping blanks — far better. | D10: =TEXTJOIN(" | ",TRUE,Data!A2,Data!D2,Data!F2,Data!K2) | E10: =_xlfn.TEXTJOIN(" | ",TRUE(),Data!A2,Data!D2,Data!F2,Data!K2) -> TX000001 | South | Compliance Suite | Bank Transfer | F10: 2nd argument TRUE = ignore empty cells. Excel 2019+.
A11: 3 | B11: LEFT | C11: First 2 characters of a transaction ID. | D11: =LEFT(Data!A2,2) | E11: =LEFT(Data!A2,2) -> TX
A12: 4 | B12: RIGHT | C12: Last 4 characters — the sequence number. | D12: =RIGHT(Data!A2,4) | E12: =RIGHT(Data!A2,4) -> 0001
A13: 5 | B13: MID | C13: Characters 3 to 8 (start position, length). | D13: =MID(Data!A2,3,6) | E13: =MID(Data!A2,3,6) -> 000001
A14: 6 | B14: TRIM | C14: Strips leading, trailing and doubled-up spaces. | D14: =TRIM($B$4) | E14: =TRIM($B$4) -> abdul AZEEZ | F14: Run this before any lookup — trailing spaces are the number one cause of failed matches.
A15: 7 | B15: UPPER | C15: Everything to capitals. | D15: =UPPER($B$4) | E15: =UPPER($B$4) -> ABDUL AZEEZ
A16: 8 | B16: LOWER | C16: Everything to lower case. | D16: =LOWER($B$5) | E16: =LOWER($B$5) -> rahul.menon@apexagi.co.in
A17: 9 | B17: PROPER | C17: Title Case — the standard name cleaner. | D17: =PROPER(TRIM($B$4)) | E17: =PROPER(TRIM($B$4)) -> Abdul Azeez | F17: TRIM + PROPER together is the workhorse combination.
A18: 10 | B18: FIND | C18: Position of the @ sign. Case-SENSITIVE. | D18: =FIND("@",$B$5) | E18: =FIND("@",$B$5) -> 12 | F18: Errors if the text isn't found — wrap in IFERROR.
A19: 11 | B19: SEARCH | C19: Same idea but case-INsensitive, and accepts wildcards. | D19: =SEARCH("MENON",$B$5) | E19: =SEARCH("MENON",$B$5) -> 7 | F19: FIND would fail here because of the capitals.
A20: 12 | B20: LEFT + FIND | C20: Pull the username out of an email address. | D20: =LEFT($B$5,FIND("@",$B$5)-1) | E20: =LEFT($B$5,FIND("@",$B$5)-1) -> rahul.menon | F20: The classic split-on-a-character pattern.
A21: 13 | B21: MID + FIND | C21: Pull the domain out of the same address. | D21: =MID($B$5,FIND("@",$B$5)+1,LEN($B$5)-FIND("@",$B$5)) | E21: =MID($B$5,FIND("@",$B$5)+1,LEN($B$5)-FIND("@",$B$5)) -> apexagi.co.in
A22: 14 | B22: SUBSTITUTE | C22: Replace text by VALUE — every hyphen becomes a slash. | D22: =SUBSTITUTE($B$6,"-"," / ") | E22: =SUBSTITUTE($B$6,"-"," / ") -> TX000045 / South / GST Filing
A23: 15 | B23: SUBSTITUTE (nth) | C23: Replace only the 2nd occurrence. | D23: =SUBSTITUTE($B$6,"-"," >> ",2) | E23: =SUBSTITUTE($B$6,"-"," >> ",2) -> TX000045-South >> GST Filing | F23: The optional 4th argument picks which occurrence.
A24: 16 | B24: REPLACE | C24: Replace text by POSITION — swap characters 1-8. | D24: =REPLACE($B$6,1,8,"TX-NEW01") | E24: =REPLACE($B$6,1,8,"TX-NEW01") -> TX-NEW01-South-GST Filing | F24: SUBSTITUTE knows what to change; REPLACE knows where.
A25: 17 | B25: LEN + SUBSTITUTE | C25: Count how many hyphens the string has. | D25: =LEN($B$6)-LEN(SUBSTITUTE($B$6,"-","")) | E25: =LEN($B$6)-LEN(SUBSTITUTE($B$6,"-","")) -> 2 | F25: A neat trick: length before minus length after.
A26: 18 | B26: MID + FIND (middle) | C26: Extract the region from the coded reference. | D26: =MID($B$6,FIND("-",$B$6)+1,FIND("-",$B$6,FIND("-",$B$6)+1)-FIND("-",$B$6)-1) | E26: =MID($B$6,FIND("-",$B$6)+1,FIND("-",$B$6,FIND("-",$B$6)+1)-FIND("-",$B$6)-1) -> South | F26: Nested FIND locates the second hyphen. Text to Columns does this without formulas.

Sheet 05_DateTime
A1: DATE & TIME
A2: TODAY · NOW · DATE · DATEDIF · EOMONTH · NETWORKDAYS · WEEKDAY
A3: INPUTS (edit the yellow cells)
A4: Row to test (2-121) | B4: 12
A5: Project start | B5: 45748
A6: Project end | B6: 46112
A8: # | B8: Function | C8: What it does | D8: Formula (copy this) | E8: Live result | F8: Notes
A9: 1 | B9: TODAY | C9: Current date. Updates every time the file opens. | D9: =TODAY() | E9: =TODAY() -> 46282 | F9: Volatile — recalculates constantly.
A10: 2 | B10: NOW | C10: Current date AND time. | D10: =NOW() | E10: =NOW() -> 46282.507 | F10: Use for timestamps on live dashboards.
A11: 3 | B11: DATE | C11: Build a date from year, month, day numbers. | D11: =DATE(2026,4,1) | E11: =DATE(2026,4,1) -> 46113 | F11: Never type dates as text — always build or enter them properly.
A12: 4 | B12: DATE (rollover) | C12: Month 13 rolls into the next year automatically. | D12: =DATE(2025,13,1) | E12: =DATE(2025,13,1) -> 46023
A13: 5 | B13: DATEDIF (days) | C13: Age of the tested transaction, in days. | D13: =DATEDIF(INDEX(Data!$C$2:$C$121,$B$4-1),TODAY(),"d") | E13: =DATEDIF(INDEX(Data!$C$2:$C$121,$B$4-1),TODAY(),"d") -> 114 | F13: Hidden function — Excel gives no tooltip. Units: "d", "m", "y".
A14: 6 | B14: DATEDIF (months) | C14: Same gap expressed in whole months. | D14: =DATEDIF(INDEX(Data!$C$2:$C$121,$B$4-1),TODAY(),"m") | E14: =DATEDIF(INDEX(Data!$C$2:$C$121,$B$4-1),TODAY(),"m") -> 3
A15: 7 | B15: DATEDIF (y/m/d) | C15: Full tenure sentence — the HR favourite. | D15: =DATEDIF($B$5,$B$6,"y")&" yr "&DATEDIF($B$5,$B$6,"ym")&" mth "&DATEDIF($B$5,$B$6,"md")&" days" | E15: =DATEDIF($B$5,$B$6,"y")&" yr "&DATEDIF($B$5,$B$6,"ym")&" mth "&DATEDIF($B$5,$B$6,"md")&" days" -> 0 yr 11 mth 30 days | F15: "ym" = leftover months, "md" = leftover days.
A16: 8 | B16: Simple subtraction | C16: Dates are just numbers — subtract them. | D16: =$B$6-$B$5 | E16: =$B$6-$B$5 -> 364 | F16: Result is a count of calendar days.
A17: 9 | B17: EOMONTH | C17: Last day of the transaction's own month. | D17: =EOMONTH(INDEX(Data!$C$2:$C$121,$B$4-1),0) | E17: =EOMONTH(INDEX(Data!$C$2:$C$121,$B$4-1),0) -> 46173 | F17: 2nd argument = months to shift.
A18: 10 | B18: EOMONTH (next) | C18: Month-end one month later — invoice due date. | D18: =EOMONTH(INDEX(Data!$C$2:$C$121,$B$4-1),1) | E18: =EOMONTH(INDEX(Data!$C$2:$C$121,$B$4-1),1) -> 46203
A19: 11 | B19: EOMONTH (start) | C19: First day of the month: month-end of the previous month, plus 1. | D19: =EOMONTH(INDEX(Data!$C$2:$C$121,$B$4-1),-1)+1 | E19: =EOMONTH(INDEX(Data!$C$2:$C$121,$B$4-1),-1)+1 -> 46143 | F19: The standard month-start idiom.
A20: 12 | B20: NETWORKDAYS | C20: Working days in the project window (weekends excluded). | D20: =NETWORKDAYS($B$5,$B$6) | E20: =NETWORKDAYS($B$5,$B$6) -> 261 | F20: Add a 3rd argument — a range of holiday dates — to exclude those too.
A21: 13 | B21: NETWORKDAYS (SLA) | C21: Working days elapsed since the transaction. | D21: =NETWORKDAYS(INDEX(Data!$C$2:$C$121,$B$4-1),TODAY()) | E21: =NETWORKDAYS(INDEX(Data!$C$2:$C$121,$B$4-1),TODAY()) -> 83 | F21: The standard way to measure an SLA.
A22: 14 | B22: WEEKDAY | C22: Day number, Monday = 1. | D22: =WEEKDAY(INDEX(Data!$C$2:$C$121,$B$4-1),2) | E22: =WEEKDAY(INDEX(Data!$C$2:$C$121,$B$4-1),2) -> 2 | F22: 2nd argument 2 = Mon-Sun. Default 1 = Sun-Sat.
A23: 15 | B23: WEEKDAY + IF | C23: Was it booked on a weekend? | D23: =IF(WEEKDAY(INDEX(Data!$C$2:$C$121,$B$4-1),2)>5,"Weekend","Weekday") | E23: =IF(WEEKDAY(INDEX(Data!$C$2:$C$121,$B$4-1),2)>5,"Weekend","Weekday") -> Weekday
A24: 16 | B24: TEXT + date | C24: Format a date as readable text. | D24: =TEXT(INDEX(Data!$C$2:$C$121,$B$4-1),"DD-MMM-YYYY") | E24: =TEXT(INDEX(Data!$C$2:$C$121,$B$4-1),"DD-MMM-YYYY") -> 26-May-2026 | F24: "MMMM" = full month name, "DDDD" = full day name.
A25: 17 | B25: YEAR / MONTH | C25: Pull the parts out — essential for pivot grouping. | D25: =TEXT(INDEX(Data!$C$2:$C$121,$B$4-1),"MMM")&"-"&YEAR(INDEX(Data!$C$2:$C$121,$B$4-1)) | E25: =TEXT(INDEX(Data!$C$2:$C$121,$B$4-1),"MMM")&"-"&YEAR(INDEX(Data!$C$2:$C$121,$B$4-1)) -> May-2026
A26: 18 | B26: SUMIFS on dates | C26: FY 2025-26 sales (1 Apr 2025 to 31 Mar 2026). | D26: =SUMIFS(Data!$H$2:$H$121,Data!$C$2:$C$121,">="&DATE(2025,4,1),Data!$C$2:$C$121,"<="&DATE(2026,3,31)) | E26: =SUMIFS(Data!$H$2:$H$121,Data!$C$2:$C$121,">="&DATE(2025,4,1),Data!$C$2:$C$121,"<="&DATE(2026,3,31)) -> 1936198.3 | F26: Use DATE() inside the criteria — never a typed date string.

Sheet 06_DataTools
A1: DATA TOOLS
A2: Data Validation · Conditional Formatting · Pivot Tables · Text to Columns · Remove Duplicates
A4: 1 · DATA VALIDATION (drop-downs)
A5: Already live on this sheet AND on the Data sheet (columns D, F and L). Click a yellow cell below for the arrow.
A6: Pick a region | B6: South | C6: List source: Master!A10:A15
A7: Pick a product | B7: Payroll | C7: List source: Master!A2:A6
A8: Quantity (1-100 only) | B8: 5 | C8: Try typing 500 — Excel will reject it.
A10: Step 1 | B10: Select the cells that need the drop-down.
A11: Step 2 | B11: Data tab > Data Validation > Settings > Allow: List.
A12: Step 3 | B12: In Source, either type values separated by commas, or select a range such as Master!A2:A6.
A13: Step 4 | B13: Use the Input Message tab for a helper tooltip and Error Alert to block bad entries.
A14: Step 5 | B14: Tip: turn the source range into a Table (Ctrl+T) so the list grows automatically.
A16: 2 · CONDITIONAL FORMATTING
A17: Three rules are already running on the Data sheet — go look at columns H, L and N.
A18: Column H | B18: Red-Yellow-Green colour scale across every sales_amount.
A19: Column L | B19: Any cell equal to "Refunded" turns red.
A20: Column N | B20: Blue data bars showing support_tickets 0-5.
A22: Step 1 | B22: Select the range. Home tab > Conditional Formatting.
A23: Step 2 | B23: Highlight Cells Rules for simple comparisons; Colour Scales / Data Bars / Icon Sets for visual ranking.
A24: Step 3 | B24: To highlight a WHOLE ROW, choose "Use a formula" and write =$L2="Refunded" — lock the column with $, leave the row unlocked.
A25: Step 4 | B25: Manage Rules lets you edit, reorder and control Stop If True.
A26: Step 5 | B26: Keep it to 2-3 rules per sheet. More than that and nothing stands out.
A28: 3 · PIVOT TABLES
A29: The Data sheet is already pivot-ready: one header row, no blanks, no merged cells.
A30: Rows | B30: region, then product
A31: Columns | B31: order_status
A32: Values | B32: sales_amount as Sum; transaction_id as Count
A33: Filters | B33: customer_type or source
A34: Try | B34: Right-click any date > Group > Months + Years for an instant trend view.
A36: Step 1 | B36: Click any cell inside the Data table.
A37: Step 2 | B37: Insert tab > PivotTable > New Worksheet > OK.
A38: Step 3 | B38: Drag fields into the Rows / Columns / Values / Filters boxes.
A39: Step 4 | B39: Change Sum to Average or Count via Value Field Settings; use "Show Values As > % of Grand Total" for share analysis.
A40: Step 5 | B40: Refresh after editing the source: PivotTable Analyze > Refresh (Alt+F5).
A41: Step 6 | B41: Insert > Slicer gives you clickable filter buttons; Insert > PivotChart turns it into a chart.
A43: 4 · TEXT TO COLUMNS
A44: Sample delimited strings below. Copy them into a blank sheet and split them.
A45: Sample (delimiter = |) | B45: Result after splitting
A46: TX000045|South|GST Filing|UPI | B46: 4 columns: id, region, product, payment
A47: TX000046|North|Payroll|Card | B47: same structure
...
